<mujocoinclude>
    <body name="base_link" pos="-0.22 0 0.889501">
        <inertial pos="0 0 0" mass="0.0" diaginertia="0.0 0.0 0.0"/>
        <geom quat="0 0 0 1" type="mesh" rgba="0.7 0.7 0.7 1" mesh="base"/>
        <body name="shoulder_link" pos="0 0 0.1807">
            <inertial pos="0 0 0" mass="7.778" diaginertia="0.0314743 0.0314743 0.0218756"/>
            <joint name="shoulder_pan_joint" pos="0 0 0" axis="0 0 1" limited="true" range="-6.28319 6.28319"/>
            <geom class="collision" quat="0 0 0 1" type="mesh" rgba="0.7 0.7 0.7 1" mesh="shoulder"/>
            <body name="upper_arm_link" pos="0 0 0" quat="0.707107 0.707107 0 0">
                <inertial pos="-0.2392 0 0.175" quat="0.707107 0 0.707107 0" mass="12.93"
                          diaginertia="0.264786 0.264786 0.0363656"/>
                <joint name="shoulder_lift_joint" pos="0 0 0" axis="0 0 1" limited="true" range="-6.28319 6.28319"/>
                <geom class="collision" pos="0 0 0.1762" quat="0.5 0.5 -0.5 -0.5" type="mesh" rgba="0.7 0.7 0.7 1"
                      mesh="upperarm"/>
                <body name="forearm_link" pos="-0.4784 0 0">
                    <inertial pos="-0.2392 0 0.0393" quat="0.707107 0 0.707107 0" mass="3.87"
                              diaginertia="0.0472382 0.0472382 0.0108844"/>
                    <joint name="elbow_joint" pos="0 0 0" axis="0 0 1" limited="true" range="-3.14159 3.14159"/>
                    <geom class="collision" pos="0 0 0.0393" quat="0.5 0.5 -0.5 -0.5" type="mesh" rgba="0.7 0.7 0.7 1"
                          mesh="forearm"/>
                    <body name="wrist_1_link" pos="-0.36 0 0.17415">
                        <inertial pos="0 0 0" quat="0.5 0.5 -0.5 0.5" mass="1.96"
                                  diaginertia="0.0055125 0.00510237 0.00510237"/>
                        <joint name="wrist_1_joint" pos="0 0 0" axis="0 0 1" limited="true" range="-6.28319 6.28319"/>
                        <geom class="collision" pos="0 0 -0.135" quat="0.707107 0.707107 0 0" type="mesh"
                              rgba="0.7 0.7 0.7 1" mesh="wrist1"/>
                        <body name="wrist_2_link" pos="0 -0.11985 -2.45816e-11" quat="0.707107 0.707107 0 0">
                            <inertial pos="0 0 0" quat="0.5 0.5 -0.5 0.5" mass="1.96"
                                      diaginertia="0.0055125 0.00497495 0.00497495"/>
                            <joint name="wrist_2_joint" pos="0 0 0" axis="0 0 1" limited="true"
                                   range="-6.28319 6.28319"/>
                            <geom class="collision" pos="0 0 -0.12" type="mesh" rgba="0.7 0.7 0.7 1" mesh="wrist2"/>
                            <body name="wrist_3_link" pos="0 0.11655 -2.39048e-11" quat="0.707107 -0.707107 0 0">
                                <inertial pos="0.0118445 -0.00802136 0.0596505"
                                          quat="0.985709 -0.115236 0.12203 0.0143892" mass="0.202"
                                          diaginertia="0.0001443 0.0001443 0.0002045"/>
                                <joint name="wrist_3_joint" pos="0 0 0" axis="0 0 1" limited="true"
                                       range="-6.28319 6.28319"/>
                                <geom class="collision" pos="0 0 -0.1168" quat="0.707107 0.707107 0 0" type="mesh"
                                      rgba="0.7 0.7 0.7 1" mesh="wrist3"/>
                                <geom size="0.005 0.005 0.005" pos="0 0 -0.01" quat="0.5 0.5 -0.5 0.5" type="box"/>
                                <geom type="mesh" rgba="0.43 1 0.84 1" mesh="eye" mass="0.1"/>
                                <!--                                    <geom pos="0.0001443 -0.0012069 0.014199" type="mesh" rgba="1 0.6 1 1" mesh="hex" />-->
                                <body name="hex" pos="0.0001443 -0.0012069 0.014199">
                                    <inertial mass="0.35" pos="0 0 0" diaginertia="0.0000452 0.0000429 0.0000839"/>
                                    <geom type="mesh" rgba="1 0.6 1 1" mesh="hex"/>
                                    <site name="hex_sensor" pos="0 0 0" size="0.001 0.001 0.002" rgba="1 0 0 1"/>

                                    <include file="./include/sander.xml"/>
                                    <!--                                            <include file="./include/spindle.xml"/>-->
                                </body>
                            </body>
                        </body>
                    </body>
                </body>
            </body>
        </body>
    </body>
</mujocoinclude>