<?xml version="1.0" ?>
<!-- =================================================================================== -->
<!-- |    This document was autogenerated by xacro from /home/zhengzhouyi/test/src/fmauch_universal_robot/ur_e_description/urdf/ur16e_robot.urdf.xacro | -->
<!-- |    EDITING THIS FILE BY HAND IS NOT RECOMMENDED                                 | -->
<!-- =================================================================================== -->
<robot name="ur16e" xmlns:xacro="http://ros.org/wiki/xacro">
    <gazebo>
        <plugin filename="libgazebo_ros_control.so" name="ros_control">
            <!--robotNamespace>/</robotNamespace-->
            <!--robotSimType>gazebo_ros_control/DefaultRobotHWSim</robotSimType-->
            <legacyModeNS>true</legacyModeNS>
        </plugin>
        <!--
    <plugin name="gazebo_ros_power_monitor_controller" filename="libgazebo_ros_power_monitor.so">
      <alwaysOn>true</alwaysOn>
      <updateRate>1.0</updateRate>
      <timeout>5</timeout>
      <powerStateTopic>power_state</powerStateTopic>
      <powerStateRate>10.0</powerStateRate>
      <fullChargeCapacity>87.78</fullChargeCapacity>     
      <dischargeRate>-474</dischargeRate>
      <chargeRate>525</chargeRate>
      <dischargeVoltage>15.52</dischargeVoltage>
      <chargeVoltage>16.41</chargeVoltage>
    </plugin>
-->
    </gazebo>
    <link name="workpiece">
        
<inertial>
            <origin rpy="0 0 0" xyz="0.0252945997895013 0.00291794469929284 0.000807439060155252" />
            <mass value="0.0341274760474065" />
            <inertia ixx="2.19523003620356E-06" ixy="4.03156111770727E-11" ixz="6.32315651210046E-12" iyy="2.19505843551914E-06" iyz="-1.31840831726533E-10" izz="2.19497449487737E-06" />
        </inertial>

        <visual>
            <origin rpy="0 0 0" xyz="0 0 0" />
            <geometry>
                <mesh filename="package://ur_e_description/meshes/ur16e/collision/workpiece.STL" />
            </geometry>
            <material name="">
                <color rgba="1 1 1 1" />
            </material>
        </visual>
        <collision>
            <origin rpy="0 0 0" xyz="0 0 0" />
            <geometry>
                <mesh filename="package://ur_e_description/meshes/ur16e/collision/workpiece.STL" />
            </geometry>
        </collision>
    </link>
    <!--
  Author: Kelsey Hawkins
  Contributers: Jimmy Da Silva, Ajit Krisshna N L, Muhammad Asif Rana
-->
    <link name="desktop">
        
<inertial>
            <origin rpy="0 0 0" xyz="-0.000372852342487157 0.000943298577969154 0.54917670437207" />
            <mass value="352.246895335311" />
            <inertia ixx="36.9019896952848" ixy="-0.000178564485501759" ixz="-0.000267585968618668" iyy="9.02850601980096" iyz="-1.13551852828308E-05" izz="42.2938482409942" />
        </inertial>

        <visual>
            <origin rpy="0 0 0" xyz="0 0 0" />
            <geometry>
                <mesh filename="package://ur_e_description/meshes/ur16e/collision/desktop.STL" />
            </geometry>
            <material name="">
                <color rgba="0.8 0.8 0.8 1" />
            </material>
        </visual>
        <collision>
            <origin rpy="0 0 0" xyz="0 0 0" />
            <geometry>
                <mesh filename="package://ur_e_description/meshes/ur16e/collision/desktop.STL" />
            </geometry>
        </collision>
    </link>
    <link name="cammera_component1">
        
<inertial>
            <origin rpy="0 0 0" xyz="-6.53466021688365E-05 -1.84373914753899E-05 0.531248218975764" />
            <mass value="1.33686906280005" />
            <inertia ixx="0.162096932311439" ixy="4.71289995930466E-07" ixz="1.29133433806864E-06" iyy="0.162096028176113" iyz="4.5977596402233E-07" izz="0.000925713309178419" />
        </inertial>

        <visual>
            <origin rpy="0 0 0" xyz="0 0 0" />
            <geometry>
                <mesh filename="package://ur_e_description/meshes/ur16e/collision/cammera_component1.STL" />
            </geometry>
            <material name="">
                <color rgba="1 0.67 0.55 1" />
            </material>
        </visual>
        <collision>
            <origin rpy="0 0 0" xyz="0 0 0" />
            <geometry>
                <mesh filename="package://ur_e_description/meshes/ur16e/collision/cammera_component1.STL" />
            </geometry>
        </collision>
    </link>
    <joint name="cammera_joint1" type="fixed">
        <origin rpy="0 0 0" xyz="-0.449999999999985 0.535392876906652 0.869501081197746" />
        <parent link="desktop" />
        <child link="cammera_component1" />
        <axis xyz="0 0 0" />
    </joint>
    <link name="cammera_component2">
        
<inertial>
            <origin rpy="0 0 0" xyz="0.0143743334390454 0.000639422840476356 0.0145471776943142" />
            <mass value="0.0691028443912137" />
            <inertia ixx="1.79722276367496E-05" ixy="1.56304807036719E-06" ixz="1.05219113367642E-06" iyy="5.89679837964793E-05" iyz="-2.00083778911943E-08" izz="6.41959769659985E-05" />
        </inertial>

        <visual>
            <origin rpy="0 0 0" xyz="0 0 0" />
            <geometry>
                <mesh filename="package://ur_e_description/meshes/ur16e/collision/cammera_component2.STL" />
            </geometry>
            <material name="">
                <color rgba="0.89 0.73 1 1" />
            </material>
        </visual>
        <collision>
            <origin rpy="0 0 0" xyz="0 0 0" />
            <geometry>
                <mesh filename="package://ur_e_description/meshes/ur16e/collision/cammera_component2.STL" />
            </geometry>
        </collision>
    </link>
    <joint name="cammera_joint2" type="fixed">
        <origin rpy="0 0 0" xyz="0 0 1.3186" />
        <parent link="cammera_component1" />
        <child link="cammera_component2" />
        <axis xyz="0 0 0" />
    </joint>
    <link name="cammera_component3">
        
<inertial>
            <origin rpy="0 0 0" xyz="-1.11022302462516E-16 4.44089209850063E-16 0.266275438540981" />
            <mass value="0.188495559215388" />
            <inertia ixx="0.00565957916544201" ixy="1.0257039595411E-21" ixz="-1.74014526552181E-19" iyy="0.00565957916544201" iyz="-1.35944526398186E-18" izz="9.42477796076938E-06" />
        </inertial>

        <visual>
            <origin rpy="0 0 0" xyz="0 0 0" />
            <geometry>
                <mesh filename="package://ur_e_description/meshes/ur16e/collision/cammera_component3.STL" />
            </geometry>
            <material name="">
                <color rgba="0.78 0.78 0.66 1" />
            </material>
        </visual>
        <collision>
            <origin rpy="0 0 0" xyz="0 0 0" />
            <geometry>
                <mesh filename="package://ur_e_description/meshes/ur16e/collision/cammera_component3.STL" />
            </geometry>
        </collision>
    </link>
    <joint name="cammera_joint3" type="fixed">
        <origin rpy="-1.5708 0 3.1416" xyz="0.032 0.02 0.015" />
        <parent link="cammera_component2" />
        <child link="cammera_component3" />
        <axis xyz="0 0 0" />
    </joint>
    <link name="cammera_component4">
        
<inertial>
            <origin rpy="0 0 0" xyz="-0.000134442645113975 -1.11022302462516E-16 0.0127931568523847" />
            <mass value="0.0419414203500108" />
            <inertia ixx="1.21191868071194E-05" ixy="-9.24881254391033E-20" ixz="-1.51078988615011E-07" iyy="2.45498574120977E-05" iyz="2.94174049703761E-21" izz="1.67799604370529E-05" />
        </inertial>

        <visual>
            <origin rpy="0 0 0" xyz="0 0 0" />
            <geometry>
                <mesh filename="package://ur_e_description/meshes/ur16e/collision/cammera_component4.STL" />
            </geometry>
            <material name="">
                <color rgba="0.98 0.80 0.68 1" />
            </material>
        </visual>
        <collision>
            <origin rpy="0 0 0" xyz="0 0 0" />
            <geometry>
                <mesh filename="package://ur_e_description/meshes/ur16e/collision/cammera_component4.STL" />
            </geometry>
        </collision>
    </link>
    <joint name="cammera_joint4" type="fixed">
        <origin rpy="-1.5708 0 0" xyz="0 0 0.547" />
        <parent link="cammera_component3" />
        <child link="cammera_component4" />
        <axis xyz="0 0 0" />
    </joint>
    <link name="cammera_component5">
        
<inertial>
            <origin rpy="0 0 0" xyz="0.00020708637264244 -8.4772382712206E-05 0.0117002403879938" />
            <mass value="0.0455860608368053" />
            <inertia ixx="4.17897109696785E-06" ixy="-6.00863307258074E-10" ixz="-1.07652910688851E-07" iyy="2.86840613498516E-05" iyz="6.7566105304779E-09" izz="2.84218973102548E-05" />
        </inertial>

        <visual>
            <origin rpy="0 0 0" xyz="0 0 0" />
            <geometry>
                <mesh filename="package://ur_e_description/meshes/ur16e/collision/cammera_component5.STL" />
            </geometry>
            <material name="">
                <color rgba="0.99 0.62 0.60 1" />
            </material>
        </visual>
        <collision>
            <origin rpy="0 0 0" xyz="0 0 0" />
            <geometry>
                <mesh filename="package://ur_e_description/meshes/ur16e/collision/cammera_component5.STL" />
            </geometry>
        </collision>
    </link>
    <joint name="cammera_joint5" type="fixed">
        <origin rpy="0 0 0" xyz="0 0 0.03" />
        <parent link="cammera_component4" />
        <child link="cammera_component5" />
        <axis xyz="0 0 0" />
    </joint>
    <link name="grit_changer_component">
        
<inertial>
            <origin rpy="0 0 0" xyz="-0.0668885277683448 -0.0165934845286996 0.0127641458540639" />
            <mass value="0.651654719391874" />
            <inertia ixx="0.00190749162464217" ixy="-9.59243134426359E-05" ixz="-2.07748091833753E-05" iyy="0.00377893603897124" iyz="-4.74173473837406E-07" izz="0.00553124681193774" />
        </inertial>

        <visual>
            <origin rpy="0 0 0" xyz="0 0 0" />
            <geometry>
                <mesh filename="package://ur_e_description/meshes/ur16e/collision/grit_changer_component.STL" />
            </geometry>
            <material name="">
                <color rgba="0.99 0.62 0.60 1" />
            </material>
        </visual>
        <collision>
            <origin rpy="0 0 0" xyz="0 0 0" />
            <geometry>
                <mesh filename="package://ur_e_description/meshes/ur16e/collision/grit_changer_component.STL" />
            </geometry>
        </collision>
    </link>
    <joint name="grit_changer_joint" type="fixed">
        <origin rpy="0 0 0" xyz="0.035643 0.53852 0.8695" />
        <parent link="desktop" />
        <child link="grit_changer_component" />
        <axis xyz="0 0 0" />
    </joint>
    <link name="base_plane_component">
        
<inertial>
            <origin rpy="0 0 0" xyz="-3.00866102864727E-17 1.11022302462516E-16 0.00998850110394323" />
            <mass value="1.55327670683259" />
            <inertia ixx="0.0101907362993274" ixy="-1.084102910812E-17" ixz="-6.75684954501936E-19" iyy="0.0101907362993274" iyz="-5.02856395104067E-19" izz="0.0202780236318419" />
        </inertial>

        <visual>
            <origin rpy="0 0 0" xyz="0 0 0" />
            <geometry>
                <mesh filename="package://ur_e_description/meshes/ur16e/collision/base_plane_component.STL" />
            </geometry>
            <material name="">
                <color rgba="0.56 1 0.96 1" />
            </material>
        </visual>
        <collision>
            <origin rpy="0 0 0" xyz="0 0 0" />
            <geometry>
                <mesh filename="package://ur_e_description/meshes/ur16e/collision/base_plane_component.STL" />
            </geometry>
        </collision>
    </link>
    <joint name="base_plane_joint" type="fixed">
        <origin rpy="0 0 3.1415926535897932" xyz="0.219999999999995 0 0.869501081197723" />
        <parent link="desktop" />
        <child link="base_plane_component" />
        <axis xyz="0 0 0" />
    </joint>
    <link name="eye">
        
<inertial>
            <origin rpy="0 0 0" xyz="-0.000958863102890152 -0.0655124855458033 0.0104442515506282" />
            <mass value="0.282" />
            <inertia ixx="6.17843742720239E-05" ixy="2.52567756760009E-08" ixz="1.26321563727462E-07" iyy="5.9094809597181E-05" iyz="-1.16145518027472E-06" izz="0.000114003036046203" />
        </inertial>

        <visual>
            <origin rpy="0 0 0" xyz="0 0 0" />
            <geometry>
                <mesh filename="package://ur_e_description/meshes/ur16e/collision/eye.STL" />
            </geometry>
            <material name="">
                <color rgba="0.43 1 0.84 1" />
            </material>
        </visual>
        <collision>
            <origin rpy="0 0 0" xyz="0 0 0" />
            <geometry>
                <mesh filename="package://ur_e_description/meshes/ur16e/collision/eye.STL" />
            </geometry>
        </collision>
    </link>
    <link name="hex">
        
<inertial>
            <origin rpy="0 0 0" xyz="0.000587122400365112 0.0059702807420467 0.0166523630424033" />
            <mass value="0.35" />
            <inertia ixx="4.52843843857233E-05" ixy="5.89457577856411E-08" ixz="2.75551028042475E-07" iyy="4.29182280763101E-05" iyz="-7.32875183539306E-07" izz="8.39068006060456E-05" />
        </inertial>

        <visual>
            <origin rpy="0 0 0" xyz="0 0 0" />
            <geometry>
                <mesh filename="package://ur_e_description/meshes/ur16e/collision/hex.STL" />
            </geometry>
            <material name="">
                <color rgba="1 0.6 1 1" />
            </material>
        </visual>
        <collision>
            <origin rpy="0 0 0" xyz="0 0 0" />
            <geometry>
                <mesh filename="package://ur_e_description/meshes/ur16e/collision/hex.STL" />
            </geometry>
        </collision>
    </link>
    <joint name="hex_joint" type="fixed">
        <origin rpy="0 0 0" xyz="0.0001443 -0.0012069 0.014199" />
        <parent link="eye" />
        <child link="hex" />
        <axis xyz="0 0 0" />
    </joint>
    <link name="sander">
        
<inertial>
            <origin rpy="0 0 3.1415926535897932" xyz="0.0210340465013133 0.000121459812366942 0.0522051139963402" />
            <mass value="1.144" />
            <inertia ixx="0.000316067729413815" ixy="9.79976270647472E-07" ixz="3.20933975887805E-05" iyy="0.000557455525495263" iyz="2.32907568883663E-07" izz="0.000723387084739462" />
        </inertial>

        <visual>
            <origin rpy="0 0 3.1415926535897932" xyz="0 0 0" />
            <geometry>
                <mesh filename="package://ur_e_description/meshes/ur16e/collision/sander.STL" />
            </geometry>
            <material name="">
                <color rgba="0.86 1 0.53 1" />
            </material>
        </visual>
        <collision>
            <origin rpy="0 0 3.1415926535897932" xyz="0 0 0" />
            <geometry>
                <mesh filename="package://ur_e_description/meshes/ur16e/collision/sander.STL" />
            </geometry>
        </collision>
    </link>
    <joint name="sander_joint" type="fixed">
        <origin rpy="0 0 0" xyz="0.00034908 0.0012069 0.034348" />
        <parent link="hex" />
        <child link="sander" />
        <axis xyz="0 0 0" />
    </joint>
    <!-- measured from model -->
    <link name="base_link">
        <visual>
            <origin rpy="0 0 3.14159265359" xyz="0 0 0" />
            <geometry>
                <mesh filename="package://ur_e_description/meshes/ur10e/visual/base.dae" />
            </geometry>
            <material name="LightGrey">
                <color rgba="0.7 0.7 0.7 1.0" />
            </material>
        </visual>
        <collision>
            <origin rpy="0 0 3.14159265359" xyz="0 0 0" />
            <geometry>
                <mesh filename="package://ur_e_description/meshes/ur10e/collision/base.stl" />
            </geometry>
        </collision>
        
<inertial>
            <mass value="4.0" />
            <origin rpy="0 0 0" xyz="0.0 0.0 0.0" />
            <inertia ixx="0.0061063308908" ixy="0.0" ixz="0.0" iyy="0.0061063308908" iyz="0.0" izz="0.01125" />
        </inertial>

    </link>
    <joint name="shoulder_pan_joint" type="revolute">
        <parent link="base_link" />
        <child link="shoulder_link" />
        <origin rpy="0 0 3.14159265359" xyz="0 0 0.1807" />
        <axis xyz="0 0 1" />
        <limit effort="330.0" lower="-6.28318530718" upper="6.28318530718" velocity="3.14" />
        <dynamics damping="0.0" friction="0.0" />
    </joint>
    <link name="shoulder_link">
        <visual>
            <origin rpy="0 0 3.14159265359" xyz="0 0 0" />
            <geometry>
                <mesh filename="package://ur_e_description/meshes/ur10e/visual/shoulder.dae" />
            </geometry>
            <material name="LightGrey">
                <color rgba="0.7 0.7 0.7 1.0" />
            </material>
        </visual>
        <collision>
            <origin rpy="0 0 3.14159265359" xyz="0 0 0" />
            <geometry>
                <mesh filename="package://ur_e_description/meshes/ur10e/collision/shoulder.stl" />
            </geometry>
        </collision>
        
<inertial>
            <mass value="7.778" />
            <origin rpy="0 0 0" xyz="0.0 0.0 0.0" />
            <inertia ixx="0.0314743125769" ixy="0.0" ixz="0.0" iyy="0.0314743125769" iyz="0.0" izz="0.021875625" />
        </inertial>

    </link>
    <joint name="shoulder_lift_joint" type="revolute">
        <parent link="shoulder_link" />
        <child link="upper_arm_link" />
        <origin rpy="1.570796327 0 0" xyz="0 0 0" />
        <axis xyz="0 0 1" />
        <limit effort="330.0" lower="-6.28318530718" upper="6.28318530718" velocity="3.14" />
        <dynamics damping="0.0" friction="0.0" />
    </joint>
    <link name="upper_arm_link">
        <visual>
            <origin rpy="1.57079632679 0 -1.57079632679" xyz="0 0 0.1762" />
            <geometry>
                <mesh filename="package://ur_e_description/meshes/ur16e/visual/upperarm.dae" />
            </geometry>
            <material name="LightGrey">
                <color rgba="0.7 0.7 0.7 1.0" />
            </material>
        </visual>
        <collision>
            <origin rpy="1.57079632679 0 -1.57079632679" xyz="0 0 0.1762" />
            <geometry>
                <mesh filename="package://ur_e_description/meshes/ur16e/collision/upperarm.stl" />
            </geometry>
        </collision>
        
<inertial>
            <mass value="12.93" />
            <origin rpy="0 1.57079632679 0" xyz="-0.2392 0.0 0.175" />
            <inertia ixx="0.264786424985" ixy="0.0" ixz="0.0" iyy="0.264786424985" iyz="0.0" izz="0.036365625" />
        </inertial>

    </link>
    <joint name="elbow_joint" type="revolute">
        <parent link="upper_arm_link" />
        <child link="forearm_link" />
        <origin rpy="0 0 0" xyz="-0.4784 0 0" />
        <axis xyz="0 0 1" />
        <limit effort="150.0" lower="-3.14159265359" upper="3.14159265359" velocity="3.14" />
        <dynamics damping="0.0" friction="0.0" />
    </joint>
    <link name="forearm_link">
        <visual>
            <origin rpy="1.57079632679 0 -1.57079632679" xyz="0 0 0.0393" />
            <geometry>
                <mesh filename="package://ur_e_description/meshes/ur16e/visual/forearm.dae" />
            </geometry>
            <material name="LightGrey">
                <color rgba="0.7 0.7 0.7 1.0" />
            </material>
        </visual>
        <collision>
            <origin rpy="1.57079632679 0 -1.57079632679" xyz="0 0 0.0393" />
            <geometry>
                <mesh filename="package://ur_e_description/meshes/ur16e/collision/forearm.stl" />
            </geometry>
        </collision>
        
<inertial>
            <mass value="3.87" />
            <origin rpy="0 1.57079632679 0" xyz="-0.2392 0.0 0.0393" />
            <inertia ixx="0.0472381686047" ixy="0.0" ixz="0.0" iyy="0.0472381686047" iyz="0.0" izz="0.010884375" />
        </inertial>

    </link>
    <joint name="wrist_1_joint" type="revolute">
        <parent link="forearm_link" />
        <child link="wrist_1_link" />
        <origin rpy="0 0 0" xyz="-0.36 0 0.17415" />
        <axis xyz="0 0 1" />
        <limit effort="54.0" lower="-6.28318530718" upper="6.28318530718" velocity="6.28" />
        <dynamics damping="0.0" friction="0.0" />
    </joint>
    <link name="wrist_1_link">
        <visual>
            <origin rpy="1.57079632679 0 0" xyz="0 0 -0.135" />
            <geometry>
                <mesh filename="package://ur_e_description/meshes/ur10e/visual/wrist1.dae" />
            </geometry>
            <material name="LightGrey">
                <color rgba="0.7 0.7 0.7 1.0" />
            </material>
        </visual>
        <collision>
            <origin rpy="1.57079632679 0 0" xyz="0 0 -0.135" />
            <geometry>
                <mesh filename="package://ur_e_description/meshes/ur10e/collision/wrist1.stl" />
            </geometry>
        </collision>
        
<inertial>
            <mass value="1.96" />
            <origin rpy="0 0 0" xyz="0.0 0.0 0.0" />
            <inertia ixx="0.00510237163405" ixy="0.0" ixz="0.0" iyy="0.00510237163405" iyz="0.0" izz="0.0055125" />
        </inertial>

    </link>
    <joint name="wrist_2_joint" type="revolute">
        <parent link="wrist_1_link" />
        <child link="wrist_2_link" />
        <origin rpy="1.570796327 0 0" xyz="0 -0.11985 -2.45816459076e-11" />
        <axis xyz="0 0 1" />
        <limit effort="54.0" lower="-6.28318530718" upper="6.28318530718" velocity="6.28" />
        <dynamics damping="0.0" friction="0.0" />
    </joint>
    <link name="wrist_2_link">
        <visual>
            <origin rpy="0 0 0" xyz="0 0 -0.12" />
            <geometry>
                <mesh filename="package://ur_e_description/meshes/ur10e/visual/wrist2.dae" />
            </geometry>
            <material name="LightGrey">
                <color rgba="0.7 0.7 0.7 1.0" />
            </material>
        </visual>
        <collision>
            <origin rpy="0 0 0" xyz="0 0 -0.12" />
            <geometry>
                <mesh filename="package://ur_e_description/meshes/ur10e/collision/wrist2.stl" />
            </geometry>
        </collision>
        
<inertial>
            <mass value="1.96" />
            <origin rpy="0 0 0" xyz="0.0 0.0 0.0" />
            <inertia ixx="0.00497495208502" ixy="0.0" ixz="0.0" iyy="0.00497495208502" iyz="0.0" izz="0.0055125" />
        </inertial>

    </link>
    <joint name="wrist_3_joint" type="revolute">
        <parent link="wrist_2_link" />
        <child link="wrist_3_link" />
        <origin rpy="1.57079632659 3.14159265359 3.14159265359" xyz="0 0.11655 -2.39048045935e-11" />
        <axis xyz="0 0 1" />
        <limit effort="54.0" lower="-6.28318530718" upper="6.28318530718" velocity="6.28" />
        <dynamics damping="0.0" friction="0.0" />
    </joint>
    <link name="wrist_3_link">
        <visual>
            <origin rpy="1.57079632679 0 0" xyz="0 0 -0.1168" />
            <geometry>
                <mesh filename="package://ur_e_description/meshes/ur10e/visual/wrist3.dae" />
            </geometry>
            <material name="LightGrey">
                <color rgba="0.7 0.7 0.7 1.0" />
            </material>
        </visual>
        <collision>
            <origin rpy="1.57079632679 0 0" xyz="0 0 -0.1168" />
            <geometry>
                <mesh filename="package://ur_e_description/meshes/ur10e/collision/wrist3.stl" />
            </geometry>
        </collision>
        
<inertial>
            <mass value="0.202" />
            <origin rpy="0 0 0" xyz="0.0 0.0 -0.025" />
            <inertia ixx="0.000144345775595" ixy="0.0" ixz="0.0" iyy="0.000144345775595" iyz="0.0" izz="0.000204525" />
        </inertial>

    </link>
    <joint name="ee_fixed_joint" type="fixed">
        <parent link="wrist_3_link" />
        <child link="ee_link" />
        <origin rpy="0.0 -1.57079632679 1.57079632679" xyz="0.0 0.0 0.0" />
    </joint>
    <link name="ee_link">
        <collision>
            <geometry>
                <box size="0.01 0.01 0.01" />
            </geometry>
            <origin rpy="0 0 0" xyz="-0.01 0 0" />
        </collision>
        
<inertial>
            <mass value="0.1" />
            <inertia ixx="0.03" iyy="0.03" izz="0.03" ixy="0.0" ixz="0.0" iyz="0.0" />
        </inertial>

    </link>
    
<transmission name="shoulder_pan_trans">
        <type>transmission_interface/SimpleTransmission</type>
        <joint name="shoulder_pan_joint">
            <hardwareInterface>hardware_interface/PositionJointInterface</hardwareInterface>
        </joint>
        <actuator name="shoulder_pan_motor">
            <mechanicalReduction>1</mechanicalReduction>
        </actuator>
    </transmission>
    <transmission name="shoulder_lift_trans">
        <type>transmission_interface/SimpleTransmission</type>
        <joint name="shoulder_lift_joint">
            <hardwareInterface>hardware_interface/PositionJointInterface</hardwareInterface>
        </joint>
        <actuator name="shoulder_lift_motor">
            <mechanicalReduction>1</mechanicalReduction>
        </actuator>
    </transmission>
    <transmission name="elbow_trans">
        <type>transmission_interface/SimpleTransmission</type>
        <joint name="elbow_joint">
            <hardwareInterface>hardware_interface/PositionJointInterface</hardwareInterface>
        </joint>
        <actuator name="elbow_motor">
            <mechanicalReduction>1</mechanicalReduction>
        </actuator>
    </transmission>
    <transmission name="wrist_1_trans">
        <type>transmission_interface/SimpleTransmission</type>
        <joint name="wrist_1_joint">
            <hardwareInterface>hardware_interface/PositionJointInterface</hardwareInterface>
        </joint>
        <actuator name="wrist_1_motor">
            <mechanicalReduction>1</mechanicalReduction>
        </actuator>
    </transmission>
    <transmission name="wrist_2_trans">
        <type>transmission_interface/SimpleTransmission</type>
        <joint name="wrist_2_joint">
            <hardwareInterface>hardware_interface/PositionJointInterface</hardwareInterface>
        </joint>
        <actuator name="wrist_2_motor">
            <mechanicalReduction>1</mechanicalReduction>
        </actuator>
    </transmission>
    <transmission name="wrist_3_trans">
        <type>transmission_interface/SimpleTransmission</type>
        <joint name="wrist_3_joint">
            <hardwareInterface>hardware_interface/PositionJointInterface</hardwareInterface>
        </joint>
        <actuator name="wrist_3_motor">
            <mechanicalReduction>1</mechanicalReduction>
        </actuator>
    </transmission>
    <gazebo reference="shoulder_link">
        <selfCollide>true</selfCollide>
    </gazebo>
    <gazebo reference="upper_arm_link">
        <selfCollide>true</selfCollide>
    </gazebo>
    <gazebo reference="forearm_link">
        <selfCollide>true</selfCollide>
    </gazebo>
    <gazebo reference="wrist_1_link">
        <selfCollide>true</selfCollide>
    </gazebo>
    <gazebo reference="wrist_3_link">
        <selfCollide>true</selfCollide>
    </gazebo>
    <gazebo reference="wrist_2_link">
        <selfCollide>true</selfCollide>
    </gazebo>
    <gazebo reference="ee_link">
        <selfCollide>true</selfCollide>
    </gazebo>
    <!-- ROS base_link to UR 'Base' Coordinates transform -->
    <link name="base" />
    <joint name="base_link-base_fixed_joint" type="fixed">
        <!-- NOTE: this rotation is only needed as long as base_link itself is
                 not corrected wrt the real robot (ie: rotated over 180
                 degrees)
      -->
        <origin rpy="0 0 -3.14159265359" xyz="0 0 0" />
        <parent link="base_link" />
        <child link="base" />
    </joint>
    <!-- Frame coincident with all-zeros TCP on UR controller -->
    <link name="tool0" />
    <joint name="wrist_3_link-tool0_fixed_joint" type="fixed">
        <origin rpy="0 0 0" xyz="0 0 0" />
        <parent link="wrist_3_link" />
        <child link="tool0" />
    </joint>
    <link name="world" />
    <joint name="world_joint" type="fixed">
        <parent link="world" />
        <child link="desktop" />
        <origin rpy="0.0 0.0 3.141592653589" xyz="0 0 0" />
    </joint>
    <joint name="workpiece_joint" type="fixed">
        <parent link="desktop" />
        <child link="workpiece" />
        <origin rpy="0.0 0.0 3.141592653589" xyz="1 0 1.5" />
    </joint>
    <joint name="plane_ur16e_joint" type="fixed">
        <parent link="base_plane_component" />
        <child link="base_link" />
        <origin rpy="0.0 0.0 3.141592653589" xyz="0.0 0.0 0.015" />
    </joint>
    <joint name="end_effortor_joint" type="fixed">
        <parent link="wrist_3_link" />
        <child link="eye" />
        <origin rpy="0.0 0.0 0.0" xyz="0.0 0.0 0.0" />
    </joint>
    <!-- ros_control plugin -->
    <!-- 
  <gazebo>
    <plugin name="gazebo_ros_control" filename="libgazebo_ros_control.so">
   <robotNamespace>/</robotNamespace>
      <robotSimType>gazebo_ros_control/DefaultRobotHWSim</robotSimType>
      <legacyModeNS>true</legacyModeNS>
    </plugin>
  </gazebo>
  -->
    <!---->
    <gazebo reference="hex">
        <material>Gazebo/Red</material>
        <mu1 value="10.0" />
        <mu2 value="10.0" />
        <kp value="0.3" />
        <kd value="1.0" />
        <fdir1 value="1 0 0" />
        <gravity value="true" />
    </gazebo>
    <!---->
    <gazebo reference="sander">
        <material>Gazebo/Red</material>
        <mu1 value="10.0" />
        <mu2 value="10.0" />
        <kp value="0.3" />
        <kd value="1.0" />
        <fdir1 value="1 0 0" />
        <gravity value="true" />
    </gazebo>
    <!---->
    <gazebo reference="hex">
        <material>Gazebo/Red</material>
        <mu1 value="10.0" />
        <mu2 value="10.0" />
        <kp value="0.3" />
        <kd value="1.0" />
        <fdir1 value="1 0 0" />
        <gravity value="true" />
    </gazebo>
    <!---->
    <gazebo reference="hex_joint">
        <provideFeedback>true</provideFeedback>
        <disableFixedJointLumping>true</disableFixedJointLumping>
    </gazebo>
    <!--  -->
    <gazebo>
        <plugin filename="libgazebo_ros_ft_sensor.so" name="ft_sensor">
            <updateRate>100.0</updateRate>
            <topicName>hex_sensor_topic</topicName>
            <jointName>hex_joint</jointName>
        </plugin>
    </gazebo>
    <transmission name="trans_shoulder_pan_joint">
        <type>transmission_interface/SimpleTransmission</type>
        <joint name="shoulder_pan_joint">
            <hardwareInterface>hardware_interface/EffortJointInterface</hardwareInterface>
        </joint>
        <actuator name="shoulder_pan_joint_motor">
            <hardwareInterface>hardware_interface/EffortJointInterface</hardwareInterface>
            <mechanicalReduction>1</mechanicalReduction>
        </actuator>
    </transmission>
    <transmission name="trans_shoulder_lift_joint">
        <type>transmission_interface/SimpleTransmission</type>
        <joint name="shoulder_lift_joint">
            <hardwareInterface>hardware_interface/EffortJointInterface</hardwareInterface>
        </joint>
        <actuator name="shoulder_lift_joint_motor">
            <hardwareInterface>hardware_interface/EffortJointInterface</hardwareInterface>
            <mechanicalReduction>1</mechanicalReduction>
        </actuator>
    </transmission>
    <transmission name="trans_elbow_joint">
        <type>transmission_interface/SimpleTransmission</type>
        <joint name="elbow_joint">
            <hardwareInterface>hardware_interface/EffortJointInterface</hardwareInterface>
        </joint>
        <actuator name="elbow_joint_motor">
            <hardwareInterface>hardware_interface/EffortJointInterface</hardwareInterface>
            <mechanicalReduction>1</mechanicalReduction>
        </actuator>
    </transmission>
    <transmission name="trans_wrist_1_joint">
        <type>transmission_interface/SimpleTransmission</type>
        <joint name="wrist_1_joint">
            <hardwareInterface>hardware_interface/EffortJointInterface</hardwareInterface>
        </joint>
        <actuator name="wrist_1_joint_motor">
            <hardwareInterface>hardware_interface/EffortJointInterface</hardwareInterface>
            <mechanicalReduction>1</mechanicalReduction>
        </actuator>
    </transmission>
    <transmission name="trans_wrist_2_joint">
        <type>transmission_interface/SimpleTransmission</type>
        <joint name="wrist_2_joint">
            <hardwareInterface>hardware_interface/EffortJointInterface</hardwareInterface>
        </joint>
        <actuator name="wrist_2_joint_motor">
            <hardwareInterface>hardware_interface/EffortJointInterface</hardwareInterface>
            <mechanicalReduction>1</mechanicalReduction>
        </actuator>
    </transmission>
    <transmission name="trans_wrist_3_joint">
        <type>transmission_interface/SimpleTransmission</type>
        <joint name="wrist_3_joint">
            <hardwareInterface>hardware_interface/EffortJointInterface</hardwareInterface>
        </joint>
        <actuator name="wrist_3_joint_motor">
            <hardwareInterface>hardware_interface/EffortJointInterface</hardwareInterface>
            <mechanicalReduction>1</mechanicalReduction>
        </actuator>
    </transmission>
    <gazebo>
        <plugin name="gazebo_ros_control" filename="libgazebo_ros_control.so">
            <robotNamespace>/</robotNamespace>
        </plugin>
    </gazebo>
</robot>
